<?xml version="1.0"?>
<robot name="vx300" xmlns:xacro="http://ros.org/wiki/xacro">

  <xacro:arg name="robot_name" default = "vx300"/>
  <xacro:arg name="base_link_frame" default="base_link"/>
  <xacro:arg name="show_ar_tag" default="false"/>
  <xacro:arg name="use_world_frame" default="false"/>
  <xacro:arg name="external_urdf_loc" default=""/>
  <xacro:arg name="load_gazebo_configs" default="false"/>

  <xacro:property name="urdf_loc" value="$(arg external_urdf_loc)"/>
  <xacro:property name="pi_offset" value="0.05"/>
  <xacro:property name="arm_angle_offset" value="85"/> <!--to clear SLAM cameras-->

  <material name="indigo">
    <color rgba="0.3 0.0 0.5 1.0"/>
  </material>

  <material name="blue">
    <color rgba="0.1 0.1 0.8 1.0"/>
  </material>
  
  <material name="lime">
    <color rgba="0.5 1.0 0.0 1.0"/>
  </material>
  
  <material name="gold">
    <color rgba="1.0 0.85 0.0 1.0"/>
  </material>
     
  <material name="orange">
    <color rgba="1.0 0.65 0.0 1.0"/>
  </material>
  
  <material name="red">
    <color rgba="0.7 0.1 0.1 1.0"/>
  </material>

  <material name="interbotix_black">
    <texture filename="package://interbotix_xsarm_descriptions/meshes/interbotix_black.png"/>
  </material>
  
  <xacro:if value="$(arg load_gazebo_configs)">
    <xacro:include filename="$(find interbotix_xsarm_gazebo)/config/interbotix_texture.gazebo"/>
  </xacro:if>


  <xacro:if value="$(arg use_world_frame)">
    <link name="world"/>
    <joint name="fixed" type="fixed">
      <parent link="world"/>
      <child link="$(arg robot_name)/$(arg base_link_frame)"/>
    </joint>
  </xacro:if>

  <link name="$(arg robot_name)/$(arg base_link_frame)">
    <visual>
      <origin rpy="0 0 0" xyz="0 0 0"/>
      <geometry>
        <mesh filename="package://interbotix_xsarm_descriptions/meshes/vx300_meshes/vx300_1_base_jaguar.stl" scale="0.001 0.001 0.001"/>
      </geometry>
      <material name="indigo"/>
    </visual>
    <collision>
      <origin rpy="0 0 0" xyz="0 0 0"/>
      <geometry>
        <mesh filename="package://interbotix_xsarm_descriptions/meshes/vx300_meshes/vx300_1_base_jaguar.stl" scale="0.001 0.001 0.001"/>
      </geometry>
    </collision>
    <inertial>
      <origin rpy="0 0 0" xyz="0 0 0.086"/>
      <mass value="30.0" />
      <inertia ixx="1.37911096" iyy="1.54185844" izz="2.35148148" ixy="-0.00000223" ixz="0.00000002" iyz="-0.00004109" />
    </inertial>
  </link>
  
  <joint name="waist" type="revolute">
    <parent link="$(arg robot_name)/$(arg base_link_frame)"/>
    <child link="$(arg robot_name)/shoulder_link"/>
    <origin rpy="0 0 ${pi}" xyz="0 0 0.178"/>
    <axis xyz="0 0 1"/>
    <limit effort="10" lower="${pi/6}" upper="${11*pi/6}" velocity="${pi}"/>
    <dynamics friction="0.1"/>
  </joint>

  <transmission name="trans_waist">
    <type>transmission_interface/SimpleTransmission</type>
    <joint name="waist">
      <hardwareInterface>hardware_interface/EffortJointInterface</hardwareInterface>
    </joint>
    <actuator name="waist_motor">
      <mechanicalReduction>1</mechanicalReduction>
    </actuator>
  </transmission>
    
  <link name="$(arg robot_name)/shoulder_link">
    <visual>
      <geometry>
        <mesh filename="package://interbotix_xsarm_descriptions/meshes/vx300_meshes/vx300_2_shoulder.stl" scale="0.001 0.001 0.001"/>
      </geometry>
      <origin rpy="0 0 0" xyz="0 0 0"/>
      <material name="red"/>
    </visual>
    <collision>
      <origin rpy="0 0 0" xyz="0 0 0"/>
      <geometry>
        <mesh filename="package://interbotix_xsarm_descriptions/meshes/vx300_meshes/vx300_2_shoulder.stl" scale="0.001 0.001 0.001"/>
      </geometry>
    </collision>
    <inertial>
      <origin rpy="0 0 0" xyz="0 0 0"/>
      <mass value="0.798614" />
      <inertia ixx="0.0009388000" iyy="0.0011380000" izz="0.0012010000" ixy="-0.0000000010" ixz="-0.0000000191" iyz="0.0000059568" />
    </inertial>
  </link>

  <joint name="shoulder" type="revolute">
    <parent link="$(arg robot_name)/shoulder_link"/>
    <child link="$(arg robot_name)/upper_arm_link"/>
    <origin rpy="0 0 0" xyz="0 0 0.0661"/>
    <axis xyz="0 1 0"/>
    <limit effort="20" lower="${radians(-120)}" upper="${radians(120)}" velocity="${pi}"/>
    <dynamics friction="0.1"/>
  </joint>

  <transmission name="trans_shoulder">
    <type>transmission_interface/SimpleTransmission</type>
    <joint name="shoulder">
      <hardwareInterface>hardware_interface/EffortJointInterface</hardwareInterface>
    </joint>
    <actuator name="shoulder_motor">
      <mechanicalReduction>1</mechanicalReduction>
    </actuator>
  </transmission>

  <link name="$(arg robot_name)/upper_arm_link">
    <visual>
      <origin rpy="0 0 ${pi/2}" xyz="0 0 0"/>
      <geometry>
        <mesh filename="package://interbotix_xsarm_descriptions/meshes/vx300_meshes/vx300_3_upper_arm.stl" scale="0.001 0.001 0.001"/>
      </geometry>
      <material name="interbotix_black"/>
    </visual>
    <collision>
      <origin rpy="0 0 ${pi/2}" xyz="0 0 0"/>
      <geometry>
        <mesh filename="package://interbotix_xsarm_descriptions/meshes/vx300_meshes/vx300_3_upper_arm.stl" scale="0.001 0.001 0.001"/>
      </geometry>
    </collision>
    <inertial>
      <origin rpy="0 0 ${pi/2}" xyz="0.0206949000 0.0000000004 0.2264590000"/>
      <mass value="0.792592" />
      <inertia ixx="0.0089250000" iyy="0.0089370000" izz="0.0009357000" ixy="0.0000000000" ixz="0.0000000000" iyz="0.0012010000" />
    </inertial>
  </link>

  <joint name="elbow" type="revolute">
    <parent link="$(arg robot_name)/upper_arm_link"/>
    <child link="$(arg robot_name)/forearm_link"/>
    <origin rpy="0 0 0" xyz="0.05955 0 0.3"/>
    <axis xyz="0 1 0"/>
    <limit effort="15" lower="${radians(-101)}" upper="${radians(92)}" velocity="${pi}"/>
    <dynamics friction="0.1"/>
  </joint>

  <transmission name="trans_elbow">
    <type>transmission_interface/SimpleTransmission</type>
    <joint name="elbow">
      <hardwareInterface>hardware_interface/EffortJointInterface</hardwareInterface>
    </joint>
    <actuator name="elbow_motor">
      <mechanicalReduction>1</mechanicalReduction>
    </actuator>
  </transmission>

  <link name="$(arg robot_name)/forearm_link">
    <visual>
      <origin rpy="0 0 ${pi/2}" xyz="0 0 0"/>
      <geometry>
        <mesh filename="package://interbotix_xsarm_descriptions/meshes/vx300_meshes/vx300_4_forearm.stl" scale="0.001 0.001 0.001"/>
      </geometry>
      <material name="interbotix_black"/>
    </visual>
    <collision>
      <origin rpy="0 0 ${pi/2}" xyz="0 0 0"/>
      <geometry>
        <mesh filename="package://interbotix_xsarm_descriptions/meshes/vx300_meshes/vx300_4_forearm.stl" scale="0.001 0.001 0.001"/>
      </geometry>
    </collision>
    <inertial>
      <origin rpy="0 0 ${pi/2}" xyz="0.1812650000 -0.0002065037 0.0000000000"/>
      <mass value="0.544659" />
      <inertia ixx="0.0054470000" iyy="0.0002267000" izz="0.0055740000" ixy="-0.0000119800" ixz="0.0000000000" iyz="0.0000000000" />
    </inertial>
  </link>

  <joint name="wrist_angle" type="revolute">
    <axis xyz="0 1 0"/>
    <limit effort="5" lower="${radians(-107)}" upper="${radians(128)}" velocity="${pi}"/>
    <origin rpy="0 0 0" xyz="0.3 0 0"/>
    <parent link="$(arg robot_name)/forearm_link"/>
    <child link="$(arg robot_name)/wrist_link"/>
    <dynamics friction="0.1"/>
  </joint>

  <transmission name="trans_wrist_angle">
    <type>transmission_interface/SimpleTransmission</type>
    <joint name="wrist_angle">
      <hardwareInterface>hardware_interface/EffortJointInterface</hardwareInterface>
    </joint>
    <actuator name="wrist_angle_motor">
      <mechanicalReduction>1</mechanicalReduction>
    </actuator>
  </transmission>

  <link name="$(arg robot_name)/wrist_link">
    <visual>
      <origin rpy="0 0 ${pi/2}" xyz="0 0 0"/>
      <geometry>
        <mesh filename="package://interbotix_xsarm_descriptions/meshes/vx300_meshes/vx300_5_wrist.stl" scale="0.001 0.001 0.001"/>
      </geometry>
      <material name="interbotix_black"/>
    </visual>
    <collision>
      <origin rpy="0 0 ${pi/2}" xyz="0 0 0"/>
      <geometry>
        <mesh filename="package://interbotix_xsarm_descriptions/meshes/vx300_meshes/vx300_5_wrist.stl" scale="0.001 0.001 0.001"/>
      </geometry>
    </collision>
    <inertial>
      <origin rpy="0 0 ${pi/2}" xyz="0.0467430000 -0.0000076652 0.0105650000"/>
      <mass value="0.115395" />
      <inertia ixx="0.0000463100" iyy="0.0000451400" izz="0.0000527000" ixy="0.0000000195" ixz="0.0000000023" iyz="0.0000042002" />
    </inertial>
  </link>

  <joint name="wrist_rotate" type="revolute">
    <parent link="$(arg robot_name)/wrist_link"/>
    <child link="$(arg robot_name)/spray_gun_link"/>
    <origin rpy="${pi} ${-pi/2} 0" xyz="0.069744 0 0"/>
    <axis xyz="0 0 1"/>
    <limit effort="1" lower="0" upper="${11*pi/6}" velocity="${pi}"/>
    <dynamics friction="0.1"/>
  </joint>

  <transmission name="trans_wrist_rotate">
    <type>transmission_interface/SimpleTransmission</type>
    <joint name="wrist_rotate">
      <hardwareInterface>hardware_interface/EffortJointInterface</hardwareInterface>
    </joint>
    <actuator name="wrist_rotate_motor">
      <mechanicalReduction>1</mechanicalReduction>
    </actuator>
  </transmission>
    
  <link name="$(arg robot_name)/spray_gun_link">
    <visual>
      <origin rpy="0 0 0" xyz="0 0 0"/>
      <geometry>
        <mesh filename="package://interbotix_xsarm_descriptions/meshes/vx300_meshes/vx300_6_sprayer_module.stl" scale="0.001 0.001 0.001"/>
      </geometry>
      <material name="blue"/>
    </visual>
    <collision>
      <origin rpy="0 0 0" xyz="0 0 0"/>
      <geometry>
        <mesh filename="package://interbotix_xsarm_descriptions/meshes/vx300_meshes/vx300_6_sprayer_module.stl" scale="0.001 0.001 0.001"/>
      </geometry>
    </collision>
    <inertial>
      <origin rpy="0 0 0" xyz="0.03012766 0.06849 0.05777255"/>
      <mass value="0.600"/>
      <inertia ixx="0.00254637" iyy="0.00592145" izz="0.00365772" ixy="-0.00000196" ixz="0.00123465" iyz="0.00000097"/>
    </inertial>
  </link>

  <joint name="gripper" type="revolute"> <!-- name="sprayer_to_trigger_lever" -->
    <parent link="$(arg robot_name)/spray_gun_link"/>
    <child link="$(arg robot_name)/spray_motor_lever_link"/>
    <origin rpy="${pi} 0 ${pi/2}" xyz="-0.050 0.012 0.015"/>
    <axis xyz="0 0 1"/>
    <limit effort="1000.0" velocity="0.5" lower="${pi/2}" upper="${3*pi/2}"/>
    <dynamics friction="0.1"/>
  </joint>

  <transmission name="trans_gripper">
    <type>transmission_interface/SimpleTransmission</type>
    <joint name="gripper">
      <hardwareInterface>hardware_interface/EffortJointInterface</hardwareInterface>
    </joint>
    <actuator name="gripper_motor">
      <mechanicalReduction>1</mechanicalReduction>
    </actuator>
  </transmission>
  
  <link name="$(arg robot_name)/spray_motor_lever_link">
    <visual>
      <geometry>
        <mesh filename="package://interbotix_xsarm_descriptions/meshes/vx300_meshes/vx300_7_spray_motor_lever.stl" scale="0.001 0.001 0.001"/>
      </geometry>
      <origin rpy="0 0 0" xyz="0 0 0"/>
      <material name="red"/>
    </visual>
  </link>

  <joint name="sprayer_to_spray_gun_tip" type="fixed">
    <parent link="$(arg robot_name)/spray_gun_link"/>
    <child link="$(arg robot_name)/spray_gun_tip"/>
    <origin rpy="0 0 0" xyz="0.27475 0 0.074"/>
  </joint>

  <link name="$(arg robot_name)/spray_gun_tip">
    <visual>
      <geometry>
        <sphere radius="0.001"/>
      </geometry>
      <material name="orange"/>
    </visual>
  </link>

  <joint name="sprayer_to_RH_stereocam" type="fixed">
    <parent link="$(arg robot_name)/spray_gun_link"/>
    <child link="$(arg robot_name)/sprayer_RH_stereocam"/>
    <origin rpy="-${pi/2} 0 -${pi/2}" xyz="0.085 -0.030 0.034"/>
  </joint>
    
  <link name="$(arg robot_name)/sprayer_RH_stereocam">
    <visual>
      <geometry>
        <sphere radius="0.003"/>
      </geometry>
      <material name="lime"/>
    </visual>
  </link>
 
  <joint name="sprayer_to_LH_stereocam" type="fixed">
    <parent link="$(arg robot_name)/spray_gun_link"/>
    <child link="$(arg robot_name)/sprayer_LH_stereocam"/>
    <origin rpy="-${pi/2} 0 -${pi/2}" xyz="0.085 0.030 0.034"/>
  </joint>

  <link name="$(arg robot_name)/sprayer_LH_stereocam">
    <visual>
      <geometry>
        <sphere radius="0.003"/>
      </geometry>
      <material name="lime"/>
    </visual>
  </link>

  <joint name="sprayer_to_thermal_cam" type="fixed">
    <parent link="$(arg robot_name)/spray_gun_link"/>
    <child link="$(arg robot_name)/sprayer_thermal_cam"/>
    <origin rpy="-${pi/2} 0 -${pi/2}" xyz="0.087 0 0.034"/>
  </joint>
  
  <link name="$(arg robot_name)/sprayer_thermal_cam">
    <visual>
      <geometry>
        <sphere radius="0.003"/>
      </geometry>
      <material name="gold"/>
    </visual>
  </link>
  
</robot>
