<?xml version="1.0"?>
<robot name="vx300" xmlns:xacro="http://ros.org/wiki/xacro">

  <xacro:arg name="robot_name" default = "vx300"/>
  <xacro:arg name="base_link_frame" default="base_link"/>
  <xacro:arg name="show_ar_tag" default="false"/>
  <xacro:arg name="use_world_frame" default="false"/>
  <xacro:arg name="external_urdf_loc" default=""/>
  <xacro:arg name="load_gazebo_configs" default="false"/>

  <xacro:property name="urdf_loc" value="$(arg external_urdf_loc)"/>
  <xacro:property name="pi_offset" value="0.05"/>

  <material name="blue">
    <color rgba="0.1 0.1 0.8 1.0"/>
  </material>
  
  <material name="orange">
    <color rgba="1.0 0.65 0.0 1.0"/>
  </material>
  
  <material name="lime">
    <color rgba="0.5 1.0 0.0 1.0"/>
  </material>  

  <xacro:if value="$(arg load_gazebo_configs)">
    <xacro:include filename="$(find interbotix_xsarm_gazebo)/config/interbotix_texture.gazebo"/>
  </xacro:if>

  <material name="interbotix_black">
    <texture filename="package://interbotix_xsarm_descriptions/meshes/interbotix_black.png"/>
  </material>

  <xacro:if value="$(arg use_world_frame)">
    <link name="world"/>
    <joint name="fixed" type="fixed">
      <parent link="world"/>
      <child link="$(arg robot_name)/$(arg base_link_frame)"/>
    </joint>
  </xacro:if>

  <link name="$(arg robot_name)/$(arg base_link_frame)">
    <visual>
      <origin rpy="0 0 0" xyz="0 0 0"/>
      <geometry>
        <mesh filename="package://interbotix_xsarm_descriptions/meshes/vx300_meshes/vx300_1_jaguar_base.stl" scale="0.001 0.001 0.001"/>
      </geometry>
      <material name="interbotix_black"/>
    </visual>
    <collision>
      <origin rpy="0 0 0" xyz="0 0 0"/>
      <geometry>
        <mesh filename="package://interbotix_xsarm_descriptions/meshes/vx300_meshes/vx300_1_jaguar_base.stl" scale="0.001 0.001 0.001"/>
      </geometry>
    </collision>
    <inertial>
      <origin rpy="0 0 0" xyz="-0.0534774000 -0.0005625750 0.0205961000"/>
      <mass value="0.969034" />
      <inertia ixx="0.0060240000" iyy="0.0017000000" izz="0.0071620000" ixy="0.0000471300" ixz="0.0000038510" iyz="-0.0000841500" />
    </inertial>
  </link>

  <link name="$(arg robot_name)/shoulder_link">
    <visual>
      <geometry>
        <mesh filename="package://interbotix_xsarm_descriptions/meshes/vx300_meshes/vx300_2_waist_shoulder_combo.stl" scale="0.001 0.001 0.001"/>
      </geometry>
      <origin rpy="0 0 0" xyz="0 0 0"/>
      <material name="blue"/>
    </visual>
    <collision>
      <origin rpy="0 0 0" xyz="0 0 0"/>
      <geometry>
        <mesh filename="package://interbotix_xsarm_descriptions/meshes/vx300_meshes/vx300_2_waist_shoulder_combo.stl" scale="0.001 0.001 0.001"/>
      </geometry>
    </collision>
    <inertial>
      <origin rpy="0 0 0" xyz="0 0 0"/>
      <mass value="0.798614" />
      <inertia ixx="0.0009388000" iyy="0.0011380000" izz="0.0012010000" ixy="-0.0000000010" ixz="-0.0000000191" iyz="0.0000059568" />
    </inertial>
  </link>  
  
  <joint name="waist" type="revolute">
    <parent link="$(arg robot_name)/$(arg base_link_frame)"/>
    <child link="$(arg robot_name)/shoulder_link"/>
    <origin rpy="0 0 ${pi}" xyz="0 0 0.178"/>
    <axis xyz="0 0 1"/>
    <limit effort="1" lower="${pi/6}" upper="${11*pi/6}" velocity="${pi}"/>
  </joint>

  <transmission name="trans_waist">
    <type>transmission_interface/SimpleTransmission</type>
    <joint name="waist">
      <hardwareInterface>hardware_interface/EffortJointInterface</hardwareInterface>
    </joint>
    <actuator name="waist_motor">
      <mechanicalReduction>1</mechanicalReduction>
    </actuator>
  </transmission>

  <joint name="shoulder" type="revolute">
    <axis xyz="0 1 0"/>
    <limit effort="20" lower="0" upper="${8*pi/9}" velocity="${pi}"/>
    <origin rpy="0 ${-4*pi/9} 0" xyz="0 0 0.0661"/>
    <parent link="$(arg robot_name)/shoulder_link"/>
    <child link="$(arg robot_name)/upper_arm_link"/>
    <dynamics friction="0.1"/>
  </joint>

  <transmission name="trans_shoulder">
    <type>transmission_interface/SimpleTransmission</type>
    <joint name="shoulder">
      <hardwareInterface>hardware_interface/EffortJointInterface</hardwareInterface>
    </joint>
    <actuator name="shoulder_motor">
      <mechanicalReduction>1</mechanicalReduction>
    </actuator>
  </transmission>

  <link name="$(arg robot_name)/upper_arm_link">
    <visual>
      <origin rpy="0 0 ${pi/2}" xyz="0 0 0"/>
      <geometry>
        <mesh filename="package://interbotix_xsarm_descriptions/meshes/vx300_meshes/vx300_3_upper_arm.stl" scale="0.001 0.001 0.001"/>
      </geometry>
      <material name="interbotix_black"/>
    </visual>
    <collision>
      <origin rpy="0 0 ${pi/2}" xyz="0 0 0"/>
      <geometry>
        <mesh filename="package://interbotix_xsarm_descriptions/meshes/vx300_meshes/vx300_3_upper_arm.stl" scale="0.001 0.001 0.001"/>
      </geometry>
    </collision>
    <inertial>
      <origin rpy="0 0 ${pi/2}" xyz="0.0206949000 0.0000000004 0.2264590000"/>
      <mass value="0.792592" />
      <inertia ixx="0.0089250000" iyy="0.0089370000" izz="0.0009357000" ixy="0.0000000000" ixz="0.0000000000" iyz="0.0012010000" />
    </inertial>
  </link>

  <joint name="elbow" type="revolute">
    <axis xyz="0 1 0"/>
    <limit effort="15" lower="${radians(-101)}" upper="${radians(92)}" velocity="${pi}"/>
    <origin rpy="0 0 0" xyz="0.05955 0 0.3"/>
    <parent link="$(arg robot_name)/upper_arm_link"/>
    <child link="$(arg robot_name)/forearm_link"/>
    <dynamics friction="0.1"/>
  </joint>

  <transmission name="trans_elbow">
    <type>transmission_interface/SimpleTransmission</type>
    <joint name="elbow">
      <hardwareInterface>hardware_interface/EffortJointInterface</hardwareInterface>
    </joint>
    <actuator name="elbow_motor">
      <mechanicalReduction>1</mechanicalReduction>
    </actuator>
  </transmission>

  <link name="$(arg robot_name)/forearm_link">
    <visual>
      <origin rpy="0 0 ${pi/2}" xyz="0 0 0"/>
      <geometry>
        <mesh filename="package://interbotix_xsarm_descriptions/meshes/vx300_meshes/vx300_4_forearm.stl" scale="0.001 0.001 0.001"/>
      </geometry>
      <material name="interbotix_black"/>
    </visual>
    <collision>
      <origin rpy="0 0 ${pi/2}" xyz="0 0 0"/>
      <geometry>
        <mesh filename="package://interbotix_xsarm_descriptions/meshes/vx300_meshes/vx300_4_forearm.stl" scale="0.001 0.001 0.001"/>
      </geometry>
    </collision>
    <inertial>
      <origin rpy="0 0 ${pi/2}" xyz="0.1812650000 -0.0002065037 0.0000000000"/>
      <mass value="0.544659" />
      <inertia ixx="0.0054470000" iyy="0.0002267000" izz="0.0055740000" ixy="-0.0000119800" ixz="0.0000000000" iyz="0.0000000000" />
    </inertial>
  </link>

  <joint name="wrist_angle" type="revolute">
    <axis xyz="0 1 0"/>
    <limit effort="5" lower="${radians(-107)}" upper="${radians(128)}" velocity="${pi}"/>
    <origin rpy="0 0 0" xyz="0.3 0 0"/>
    <parent link="$(arg robot_name)/forearm_link"/>
    <child link="$(arg robot_name)/wrist_link"/>
    <dynamics friction="0.1"/>
  </joint>

  <transmission name="trans_wrist_angle">
    <type>transmission_interface/SimpleTransmission</type>
    <joint name="wrist_angle">
      <hardwareInterface>hardware_interface/EffortJointInterface</hardwareInterface>
    </joint>
    <actuator name="wrist_angle_motor">
      <mechanicalReduction>1</mechanicalReduction>
    </actuator>
  </transmission>

  <link name="$(arg robot_name)/wrist_link">
    <visual>
      <origin rpy="0 0 ${pi/2}" xyz="0 0 0"/>
      <geometry>
        <mesh filename="package://interbotix_xsarm_descriptions/meshes/vx300_meshes/vx300_5_wrist.stl" scale="0.001 0.001 0.001"/>
      </geometry>
      <material name="interbotix_black"/>
    </visual>
    <collision>
      <origin rpy="0 0 ${pi/2}" xyz="0 0 0"/>
      <geometry>
        <mesh filename="package://interbotix_xsarm_descriptions/meshes/vx300_meshes/vx300_5_wrist.stl" scale="0.001 0.001 0.001"/>
      </geometry>
    </collision>
    <inertial>
      <origin rpy="0 0 ${pi/2}" xyz="0.0467430000 -0.0000076652 0.0105650000"/>
      <mass value="0.115395" />
      <inertia ixx="0.0000463100" iyy="0.0000451400" izz="0.0000527000" ixy="0.0000000195" ixz="0.0000000023" iyz="0.0000042002" />
    </inertial>
  </link>

  <link name="$(arg robot_name)/spray_gun_link">
  <visual>
    <origin rpy="0 0 0" xyz="0 0 0"/>
    <geometry>
      <mesh filename="package://interbotix_xsarm_descriptions/meshes/vx300_meshes/vx300_6_sprayer_module.stl" scale="0.001 0.001 0.001"/>
    </geometry>
    <material name="interbotix_black"/>
  </visual>
  <collision>
    <origin rpy="0 0 0" xyz="0 0 0"/>
    <geometry>
      <mesh filename="package://interbotix_xsarm_descriptions/meshes/vx300_meshes/vx300_6_sprayer_module.stl" scale="0.001 0.001 0.001"/>
    </geometry>
  </collision>
  <inertial>
    <origin rpy="0 0 0" xyz="0.0230010000 0.0000000000 0.0115230000"/>
    <mass value="0.097666" />
    <inertia ixx="0.0000326800" iyy="0.0000243600" izz="0.0000211900" ixy="0.0000000000" ixz="0.0000000000" iyz="0.0000002785" />
  </inertial>
</link>

  <joint name="wrist_rotate" type="revolute">
    <parent link="$(arg robot_name)/wrist_link"/>
    <child link="$(arg robot_name)/spray_gun_link"/>
    <origin rpy="${pi} ${-pi/2} 0" xyz="0.069744 0 0"/>
    <dynamics friction="0.1"/>
    <axis xyz="0 0 1"/>
    <limit effort="1" lower="${pi/6}" upper="${11*pi/6}" velocity="${pi}"/>
  </joint> 

  <transmission name="trans_wrist_rotate">
    <type>transmission_interface/SimpleTransmission</type>
    <joint name="wrist_rotate">
      <hardwareInterface>hardware_interface/EffortJointInterface</hardwareInterface>
    </joint>
    <actuator name="wrist_rotate_motor">
      <mechanicalReduction>1</mechanicalReduction>
    </actuator>
  </transmission>


  
  <transmission name="trans_gripper">
    <type>transmission_interface/SimpleTransmission</type>
    <joint name="gripper">
      <hardwareInterface>hardware_interface/EffortJointInterface</hardwareInterface>
    </joint>
    <actuator name="gripper_motor">
      <mechanicalReduction>1</mechanicalReduction>
    </actuator>
  </transmission>

  <link name="$(arg robot_name)/sprayer_RH_stereocam">
    <visual>
      <geometry>
        <sphere radius="0.001"/>
      </geometry>
      <material name="lime"/>
    </visual>
  </link>
  
  <joint name="sprayer_to_RH_stereocam" type="fixed">
    <parent link="$(arg robot_name)/spray_gun_link"/>
    <child link="$(arg robot_name)/sprayer_RH_stereocam"/>
    <origin rpy="-1.570796 0 -1.570796" xyz="0.085 -0.030 0.034"/>
  </joint>

  <link name="$(arg robot_name)/sprayer_LH_stereocam">
    <visual>
      <geometry>
        <sphere radius="0.001"/>
      </geometry>
      <material name="lime"/>
    </visual>
  </link>
  
  <joint name="sprayer_to_LH_stereocam" type="fixed">
    <parent link="$(arg robot_name)/spray_gun_link"/>
    <child link="$(arg robot_name)/sprayer_LH_stereocam"/>
    <origin rpy="-1.570796 0 -1.570796" xyz="0.085 0.030 0.034"/>
  </joint>

  <link name="$(arg robot_name)/sprayer_thermal_cam">
    <visual>
      <geometry>
        <sphere radius="0.001"/>
      </geometry>
      <material name="orange"/>
    </visual>
  </link>
  
  <joint name="sprayer_to_thermal_cam" type="fixed">
    <parent link="$(arg robot_name)/spray_gun_link"/>
    <child link="$(arg robot_name)/sprayer_thermal_cam"/>
    <origin rpy="-1.570796 0 -1.570796" xyz="0.087 0 0.034"/>
  </joint>
    
  <link name="$(arg robot_name)/trigger_lever">
    <visual>
      <geometry>
        <mesh filename="package://interbotix_xsarm_descriptions/meshes/vx300_meshes/vx300_7_spray_motor_lever.stl" scale="0.001 0.001 0.001"/>
      </geometry>
      <origin rpy="0 0 0" xyz="0 0 0"/>
      <material name="blue"/>
    </visual>
  </link>  
  
  <joint name="sprayer_to_trigger_lever" type="revolute">
    <parent link="$(arg robot_name)/spray_gun_link"/>
    <child link="$(arg robot_name)/trigger_lever"/>
    <origin rpy="3.14159 0 1.570796" xyz="-0.050 0.012 0.015"/>
    <axis xyz="0 0 1"/>
    <limit effort="1000.0" velocity="0.5" lower="1.570796" upper="4.712389"/>
  </joint>

  <link name="$(arg robot_name)/gripper_tip">
    <visual>
      <geometry>
        <sphere radius="0.001"/>
      </geometry>
      <material name="orange"/>
    </visual>
  </link>
  
  <joint name="sprayer_to_gripper_tip" type="fixed">
    <parent link="$(arg robot_name)/spray_gun_link"/>
    <child link="$(arg robot_name)/gripper_tip"/>
    <origin rpy="0 0 0" xyz="0.27475 0 0.074"/>
  </joint>

 <!-- <link name="$(arg robot_name)/gripper_tip"/>

  <joint name="gripper" type="revolute">
    <axis xyz="0 0 -1"/>
    <limit effort="1" lower="${-pi + pi_offset}" upper="${pi - pi_offset}" velocity="${pi}"/>
    <parent link="$(arg robot_name)/spray_gun_link"/>
    <child link="$(arg robot_name)/gripper_tip"/>
    <origin rpy="0 0 0" xyz="0 -.056 -.29"/>
    <dynamics friction="0.1"/>
  </joint>-->  
</robot>
